package pointerserrors

import (
	"testing"
)

func TestWallet(t *testing.T) {

	t.Run("Deposit", func(t *testing.T) {
		wallet := Wallet{}
		wallet.Deposit(Bitcoin(10))
		assertBalance(t, wallet, Bitcoin(10))
	})

	t.Run("Withdraw sufficient funds", func(t *testing.T) {
		wallet := Wallet{balance: Bitcoin(20)}
		err := wallet.Withdraw(Bitcoin(10))
		assertNoError(t, err)
		assertBalance(t, wallet, Bitcoin(10))
	})

	t.Run("Withdraw insufficient funds.", func(t *testing.T) {
		startingBalance := Bitcoin(20)
		wallet := Wallet{startingBalance}
		err := wallet.Withdraw(Bitcoin(100))

		assertError(t, err)
		assertBalance(t, wallet, startingBalance)
	})
}
func assertBalance(t testing.TB, wallet Wallet, want Bitcoin) {
	t.Helper()
	got := wallet.Balance()

	if got != want {
		t.Errorf("got %s want %s", got, want)
	}
}

func assertError(t testing.TB, err error)  {
	t.Helper()
	if err == nil {
		t.Fatal("Wanted an error but didn't get one.")
	}
}

func assertNoError(t testing.TB, err error) {
	t.Helper()
	if err != nil {
		t.Fatal("Didn't wanted an error but got one.")
	}
}
